Workbook

Sheet Defect_Log
A1: Defect ID | B1: Source Day | C1: Component | D1: Summary | E1: Symptom (hiện tượng) | F1: Category | G1: Severity | H1: Severity Source | I1: Priority | J1: Status | K1: Root Cause (nguyên nhân gốc) | L1: Root Cause Category | M1: Detection Phase | N1: Detection Method | O1: Owner Team (đề xuất) | P1: Detected Date | Q1: Fixed Date | R1: Last Verified | S1: Deadline | T1: Evidence | U1: Defect Kind | V1: Fixture Bug | W1: Regression | X1: Prevention Action | Y1: Ghi chú / kết quả kiểm lại
A2: DEF-001 | B2: 9 | C2: FE Quiz | D2: Không chọn được bộ đề bằng bàn phím | E2: Tab không tới các thẻ đề; Enter/Space không chọn được (KB-04) | F2: Frontend UI | G2: Medium | H2: Proposed | I2: P2 | J2: Open | K2: Thẻ đề là phần tử không focus được (không phải button/không có tabindex và role) | L2: RC10 - Component UI không theo chuẩn a11y/responsive | M2: Manual test | N2: Manual | O2: FE | P2: Not recorded | R2: 2026-10-07 | S2: Chưa xác nhận | T2: Day09_Execution_Guide_Local_A11y_Responsive_v3.xlsx | U2: Product | V2: N | W2: N | X2: PA-11 | Y2: Chưa retest ngày 05/10 | 07/10: DOM /quiz cho thấy thẻ đề là DIV có onclick, không tabindex/role; vẫn không focus được | 07/10 (Chrome, đã đăng nhập): thẻ đề vẫn là DIV không role/tabindex
A3: DEF-002 | B3: 9 | C3: FE | D3: Focus không nhìn thấy rõ trên các trang chính | E3: Khi Tab qua control, viền focus khó nhận ra (FOCUS-01) | F3: Frontend UI | G3: Medium | H3: Proposed | I3: P2 | J3: Retest | K3: Style chung bỏ outline mặc định mà không có style focus-visible thay thế | L3: RC10 - Component UI không theo chuẩn a11y/responsive | M3: Manual test | N3: Manual | O3: FE | P3: Not recorded | Q3: Not recorded | R3: 2026-10-07 | S3: Chưa xác nhận | T3: Day09_Execution_Guide_Local_A11y_Responsive_v3.xlsx | U3: Product | V3: N | W3: N | X3: PA-11 | Y3: Root cause suy từ quan sát, chưa đọc CSS | 07/10: nút header ở /quiz có viền focus nhìn rõ khi Tab; mới kiểm 1 trang, chưa kiểm video và 3 trang còn lại
A4: DEF-003 | B4: 9 | C4: FE Login | D4: Input Email/Mật khẩu không gắn label | E4: WAVE báo 2 missing form label (A11Y-BUG-003) | F4: Frontend UI | G4: Medium | H4: Recorded | I4: P2 | J4: Open | K4: Component form render <label> và <input> rời nhau: input không có id, label không có htmlFor | L4: RC10 - Component UI không theo chuẩn a11y/responsive | M4: Manual test | N4: WAVE + DOM | O4: FE | P4: Not recorded | R4: 2026-10-07 | S4: Chưa xác nhận | T4: Day09_Execution_Guide_Local_A11y_Responsive_v3.xlsx | U4: Product | V4: N | W4: N | X4: PA-11 | Y4: 05/10: DOM /login vẫn vậy (2 input không id, label for rỗng) | 07/10: DOM /login vẫn vậy
A5: DEF-004 | B5: 9 | C5: FE Register | D5: 3 input đăng ký không gắn label | E5: WAVE báo 3 missing form label và 4 orphaned label (A11Y-BUG-004) | F5: Frontend UI | G5: Medium | H5: Recorded | I5: P2 | J5: Open | K5: Dùng chung cách dựng form với trang Login (label và input không liên kết) | L5: RC10 - Component UI không theo chuẩn a11y/responsive | M5: Manual test | N5: WAVE + DOM | O5: FE | P5: Not recorded | R5: 2026-10-07 | S5: Chưa xác nhận | T5: Day09_Execution_Guide_Local_A11y_Responsive_v3.xlsx | U5: Product | V5: N | W5: N | X5: PA-11 | Y5: 05/10: DOM /register vẫn vậy | 07/10: DOM /register vẫn vậy
A6: DEF-005 | B6: 9 | C6: FE Playground | D6: Ô STDIN và dropdown bài không có accessible name | E6: WAVE báo textarea STDIN không có label tương ứng (A11Y-BUG-005) | F6: Frontend UI | G6: Medium | H6: Recorded | I6: P2 | J6: Open | K6: Text mô tả hiển thị cạnh control nhưng không liên kết bằng label/aria | L6: RC10 - Component UI không theo chuẩn a11y/responsive | M6: Manual test | N6: WAVE | O6: FE | P6: Not recorded | R6: 2026-10-07 | S6: Chưa xác nhận | T6: Day09_Execution_Guide_Local_A11y_Responsive_v3.xlsx | U6: Product | V6: N | W6: N | X6: PA-11 | Y6: Chưa retest ngày 05/10 | 07/10 (Chrome, đã đăng nhập): label 'STDIN' có nhưng không gắn với textarea (htmlFor rỗng); ô nhập và nút gửi của AI Coach cũng không có accessible name. Dropdown chọn bài đã được thay bằng lưới thẻ
A7: DEF-006 | B7: 9 | C7: FE Header | D7: Header không co lại ở tablet | E7: Ở iPad Pro, navigation và nút Đăng nhập/Đăng ký dồn sát nhau (RESP-BUG-001) | F7: Frontend UI | G7: Medium | H7: Recorded | I7: P2 | J7: Retest | K7: Header chỉ có bố cục desktop và mobile, thiếu breakpoint tablet | L7: RC10 - Component UI không theo chuẩn a11y/responsive | M7: Manual test | N7: Chrome DevTools | O7: FE | P7: Not recorded | Q7: Not recorded | R7: 2026-10-07 | S7: Chưa xác nhận | T7: Day09_Execution_Guide_Local_A11y_Responsive_v3.xlsx | U7: Product | V7: N | W7: N | X7: PA-11 | Y7: Chưa retest ngày 05/10 | 07/10: ở chiều rộng 769 px header đã gộp menu vào nút 'Thêm', không cuộn ngang; chưa kiểm ở iPad Pro 1024 px
A8: DEF-007 | B8: 9 | C8: FE Playground | D8: Ba thẻ Hint bị ép hẹp ở tablet | E8: Badge 'Đã mở/Chưa mở' tràn khỏi thẻ ở iPad Pro (RESP-BUG-002) | F8: Frontend UI | G8: Medium | H8: Recorded | I8: P2 | J8: Open | K8: Lưới 3 cột cố định, không xuống hàng theo chiều rộng | L8: RC10 - Component UI không theo chuẩn a11y/responsive | M8: Manual test | N8: Chrome DevTools | O8: FE | P8: Not recorded | R8: 2026-10-07 | S8: Chưa xác nhận | T8: Day09_Execution_Guide_Local_A11y_Responsive_v3.xlsx | U8: Product | V8: N | W8: N | X8: PA-11 | Y8: Chưa retest ngày 05/10 | 07/10 (Chrome, cửa sổ 1568 px): 3 thẻ Hint vẫn hẹp, chữ xuống 3-4 dòng, badge 'Chưa mở' không tràn; chưa kiểm ở chiều rộng iPad Pro
A9: DEF-008 | B9: 10 | C9: QA tài liệu | D9: Bảng ngưỡng hiệu năng có ô #REF! | E9: Sheet 06_Thresholds: 3 dòng Page Load hiển thị #REF! ở baseline và ngưỡng | F9: Documentation | G9: Low | H9: Proposed | I9: P3 | J9: Open | K9: Công thức tham chiếu tới ô đã bị xóa/di chuyển ở sheet 05_Page_Load sau khi sửa bố cục | L9: RC11 - Tài liệu/kết quả AI không được đối chiếu với code | M9: Local | N9: Đọc workbook | O9: QA | P9: Not recorded | R9: 2026-10-07 | S9: Chưa xác nhận | T9: Day10_Performance_Baseline_Guide.xlsx | U9: Documentation | V9: N | W9: N | X9: PA-12 | Y9: 07/10: mở lại file, sheet 06_Thresholds vẫn có #REF! ở 3 dòng Page Load
A10: DEF-009 | B10: 11 | C10: BE dữ liệu bài học | D10: 2 bài học BE thiếu mục tiêu học tập | E10: content-lint báo 2 ERROR CT004 trên be-lessons.json | F10: Content | G10: Medium | H10: Proposed | I10: P2 | J10: Open | K10: Seed bài học được viết tay trong initial-data.ts, schema không bắt buộc learningOutcome và không có bước lint trước khi merge | L10: RC03 - Nội dung/dữ liệu học liệu đưa vào không qua gate tự động | M10: Local | N10: content-lint | O10: BE | P10: 2026-09-17 | R10: 2026-10-07 | S10: Chưa xác nhận | T10: Day11_Content_Lint_Tran_Quoc_Nguyen/tools/content-lint/real-content/lint-report.json | U10: Product | V10: N | W10: N | X10: PA-03 | Y10: 05/10: bot Ngày 22 chạy lại vẫn 2 ERROR (gate advisory) | 07/10: chạy lại content-lint trên commit cb311b5, vẫn 2 ERROR CT004 (be-lessons dòng 2 và 45)
A11: DEF-010 | B11: 12 | C11: BE dữ liệu quiz | D11: Đáp án đúng dồn vào một vị trí | E11: 19/30 câu (63%) có đáp án đúng ở vị trí thứ 2; 4 câu liên tiếp cùng vị trí (QV017, QV018) | F11: Quiz | G11: Medium | H11: Proposed | I11: P2 | J11: Open | K11: Câu hỏi được soạn tay theo thói quen đặt đáp án đúng ở B, không có bước xáo/kiểm phân bố trước khi đưa vào seed | L11: RC03 - Nội dung/dữ liệu học liệu đưa vào không qua gate tự động | M11: Local | N11: quiz-validator | O11: BE | P11: 2026-09-18 | R11: 2026-10-07 | S11: Chưa xác nhận | T11: Day12_Quiz_Validator_Tran_Quoc_Nguyen/Day12_Quality_Report.xlsx | U11: Product | V11: N | W11: N | X11: PA-03 | Y11: Đo trên bộ 30 câu ngày 18/09; bộ hiện tại 60 câu chưa đo lại phân bố | 07/10: chạy lại quiz-validator trên cb311b5 (60 câu), QV017: đáp án đúng ở vị trí 1 trong 33/60 câu (55%)
A12: DEF-011 | B12: 12 | C12: BE dữ liệu quiz | D12: Đáp án lộ qua độ dài hoặc quan hệ chuỗi con | E12: QV023 ở 6 câu (đáp án đúng dài/ngắn bất thường), QV016 ở Q29-Q30 (option là chuỗi con của option khác) | F12: Quiz | G12: Low | H12: Proposed | I12: P3 | J12: Open | K12: Không có tiêu chí viết phương án nhiễu và không có validator chạy khi sửa dữ liệu quiz | L12: RC03 - Nội dung/dữ liệu học liệu đưa vào không qua gate tự động | M12: Local | N12: quiz-validator | O12: BE | P12: 2026-09-18 | R12: 2026-10-07 | S12: Chưa xác nhận | T12: Day12_Quiz_Validator_Tran_Quoc_Nguyen/Day12_Quality_Report.xlsx | U12: Product | V12: N | W12: N | X12: PA-03 | Y12: 07/10: chạy lại quiz-validator trên cb311b5, vẫn có cảnh báo QV023 và QV016
A13: DEF-012 | B13: 13 | C13: BE bài coding | D13: Bộ test bài số nguyên tố để lọt lời giải sai | E13: Mutation score 66,7% (10/15), dưới ngưỡng 80%; 5 mutant sống sót (F-D13-01) | F13: Coding Problem | G13: High | H13: Recorded | I13: P1 | J13: Open | K13: Test được viết theo ví dụ trong đề, không có test biên (bình phương số nguyên tố, n lớn) và không đo mutation trước khi phát hành | L13: RC03 - Nội dung/dữ liệu học liệu đưa vào không qua gate tự động | M13: Local | N13: Mutation test | O13: BE | P13: 2026-09-19 | S13: Chưa xác nhận | T13: Day13_Coding_Problem_Validator_Tran_Quoc_Nguyen/Day13_Quality_Report.xlsx | U13: Product | V13: N | W13: N | X13: PA-04 | Y13: Bộ test bổ sung mới ở mức đề xuất, chưa áp vào BE | 07/10: bài kiem-tra-so-nguyen-to vẫn 4 test case; file initial-exercises.ts không đổi nội dung từ 24/09. Chưa chạy lại mutation
A14: DEF-013 | B14: 13 | C14: BE bài coding | D14: 24/30 bài không nêu ràng buộc | E14: Validator báo 24 lần CP002 (F-D13-02) | F14: Coding Problem | G14: Medium | H14: Recorded | I14: P2 | J14: Open | K14: Schema Exercise không có trường constraints nên người soạn không có chỗ điền | L14: RC03 - Nội dung/dữ liệu học liệu đưa vào không qua gate tự động | M14: Local | N14: coding-problem-validator | O14: BE | P14: 2026-09-19 | R14: 2026-10-07 | S14: Chưa xác nhận | T14: Day13_Coding_Problem_Validator_Tran_Quoc_Nguyen/Day13_Quality_Report.xlsx | U14: Product | V14: N | W14: N | X14: PA-04 | Y14: 07/10: chạy lại validator trên cb311b5, vẫn 24 lần CP002
A15: DEF-014 | B15: 13 | C15: BE bài coding | D15: 3 bài quá ít test | E15: CP013 ở tim-so-lon-nhat, dao-nguoc-chuoi, day14-bang-cuu-chuong (F-D13-03) | F15: Coding Problem | G15: Low | H15: Recorded | I15: P3 | J15: Open | K15: Không có số test tối thiểu trong quy trình soạn bài | L15: RC03 - Nội dung/dữ liệu học liệu đưa vào không qua gate tự động | M15: Local | N15: coding-problem-validator | O15: BE | P15: 2026-09-19 | R15: 2026-10-07 | S15: Chưa xác nhận | T15: Day13_Coding_Problem_Validator_Tran_Quoc_Nguyen/Day13_Quality_Report.xlsx | U15: Product | V15: N | W15: N | X15: PA-04 | Y15: 07/10: chạy lại validator trên cb311b5, vẫn 3 lần CP013
A16: DEF-015 | B16: 13 | C16: BE Judge | D16: Nghi lộ input của hidden test qua stderr | E16: Mô phỏng: 2/2 hidden test của 2 bài bị echo dòng input đầu qua stderr/errorMessage (F-D13-04) | F16: AI Safety | G16: High | H16: Recorded | I16: P1 | J16: Needs verification | K16: Judge lưu và trả stderr cho cả test ẩn, không lọc theo isHidden | L16: RC05 - Không lọc thông tin nội bộ trước khi trả cho người dùng | M16: Local | N16: Đọc code + mô phỏng | O16: BE | P16: 2026-09-19 | S16: Chưa xác nhận | T16: Day13_Coding_Problem_Validator_Tran_Quoc_Nguyen/Day13_Quality_Report.xlsx | U16: Product | V16: N | W16: N | X16: PA-06 | Y16: Chưa tái hiện trên server thật
A17: DEF-016 | B17: 13 | C17: BE Judge | D17: Output đúng dài hơn 64KB bị chấm sai im lặng | E17: Reference solution bị WA với test 12.000 phần tử; stdout bị cắt ở 65.536 ký tự (F-D13-05) | F17: Backend Logic | G17: Medium | H17: Recorded | I17: P2 | J17: Open | K17: Judge cắt stdout ở MAX_OUTPUT_BYTES nhưng không có trạng thái riêng cho vượt giới hạn output | L17: RC09 - Thiếu test/gate tự động cho thay đổi | M17: Local | N17: coding-problem-validator | O17: BE | P17: 2026-09-19 | R17: 2026-10-07 | S17: Chưa xác nhận | T17: Day13_Coding_Problem_Validator_Tran_Quoc_Nguyen/Day13_Quality_Report.xlsx | U17: Product | V17: N | W17: N | X17: PA-04 | Y17: Đã thêm rule CP019 ở phía dữ liệu; hành vi judge chưa đổi | 07/10: code-runner.helper.ts vẫn cắt stdout ở MAX_OUTPUT_BYTES = 64KB
A18: DEF-017 | B18: 13 | C18: BE Judge | D18: Trạng thái bài nộp theo test fail cuối cùng | E18: Bài vừa WA vừa TLE hiển thị theo test sau cùng (F-D13-07) | F18: Backend Logic | G18: Low | H18: Recorded | I18: P3 | J18: Needs verification | K18: Mỗi test fail ghi đè status; chưa rõ có phải chủ ý thiết kế | L18: RC09 - Thiếu test/gate tự động cho thay đổi | M18: Local | N18: Đọc code | O18: BE | P18: 2026-09-19 | R18: 2026-10-07 | S18: Chưa xác nhận | T18: Day13_Coding_Problem_Validator_Tran_Quoc_Nguyen/Day13_Quality_Report.xlsx | U18: Product | V18: N | W18: N | X18: PA-04 | Y18: Cần BE xác nhận | 07/10: judge-queue.service.ts vẫn gán status theo test fail sau cùng; chú thích trong CodePlaygroundPage.tsx mô tả đây là hành vi có chủ ý. Cần BE xác nhận
A19: DEF-018 | B19: 13 | C19: BE Exercise API | D19: Gợi ý tầng 3 trùng lời giải và có thể lộ qua API chi tiết bài | E19: 20/20 bài Ngày 14 có hint3 trùng nguyên văn solutionCode; findBySlug select cả hints (F-D13-08) | F19: AI Safety | G19: High | H19: Recorded | I19: P1 | J19: Retest | K19: API chi tiết bài trả nguyên object hints, bỏ qua cơ chế mở khóa gợi ý | L19: RC05 - Không lọc thông tin nội bộ trước khi trả cho người dùng | M19: Local | N19: Đọc code + đếm | O19: BE | P19: 2026-09-19 | Q19: Not recorded | R19: 2026-10-07 | S19: Chưa xác nhận | T19: Day13_Coding_Problem_Validator_Tran_Quoc_Nguyen/Day13_Quality_Report.xlsx | U19: Product | V19: N | W19: N | X19: PA-06 | Y19: 05/10: GET /exercises/:slug không còn trường hints trên bài kiểm được; DB local chỉ có 1 bài code nên chưa kết luận cho 20 bài | 07/10: kết quả như ngày 05/10
A20: DEF-019 | B20: 14 | C20: demo1 API (ngoài Learning Hub) | D20: Mã phim không tồn tại trả 500 | E20: LayThongTinPhim?MaPhim=999999 trả 500 'Mã phim không hợp lệ!' thay vì 404 (RF-003) | F20: API Contract | G20: High | H20: Recorded | I20: P1 | J20: Open | K20: Không xác định được từ bên ngoài (không có source); biểu hiện giống thiếu xử lý trường hợp không tìm thấy | L20: RC01 - Không validate kiểu/định dạng input ở API | M20: Manual test | N20: Gọi API | O20: Ngoài nhóm | P20: 2026-09-22 | S20: Chưa xác nhận | T20: Day14_Bo lab tester thuc te/Day14_Tester_Labs_Quality_Report_GitHub.xlsx | U20: External | V20: N | W20: N | Y20: Hệ thống demo dùng chung, không thuộc phạm vi sửa của nhóm
A21: DEF-020 | B21: 18 | C21: Data-AI Retrieval | D21: MRR giảm sau khi thêm rerank | E21: MRR 0,9750 (Ngày 17) xuống 0,9667 (Ngày 18); Recall@5 giữ 100% | F21: RAG Retrieval | G21: Low | H21: Proposed | I21: P3 | J21: Needs verification | K21: Chưa xác định: báo cáo ghi nhóm CAT 09 (số liệu, thời hạn) chỉ đạt rank 2 sau rerank; chưa có ngưỡng chấp nhận regression | L21: RC09 - Thiếu test/gate tự động cho thay đổi | M21: Local | N21: Benchmark | O21: Data-AI | P21: 2026-09-27 | S21: Chưa xác nhận | T21: day_16_toi_day21_test/day18/Bao_Cao_Ngay_18_Hybrid_Search_Tran_Quoc_Nguyen.docx | U21: Product | V21: N | W21: Y | X21: PA-10 | Y21: Cần Data-AI quyết định có chấp nhận đánh đổi
A22: DEF-021 | B22: 19 | C22: BE AI Coach | D22: AI Coach không nhận diện yêu cầu không phù hợp với trẻ | E22: 10 case RT-041..RT-050: trả lời fallback về bài tập, không từ chối rõ, không hướng dẫn tìm hỗ trợ | F22: AI Safety | G22: High | H22: Recorded | I22: P1 | J22: Open | K22: Bộ lọc trước LLM chỉ có nhánh prompt injection; không có nhánh child safety nên câu hỏi rơi vào trả lời mặc định | L22: RC04 - Guardrail AI chưa phủ tình huống | M22: Manual test | N22: Red-team thủ công | O22: BE | P22: 2026-10-01 | R22: 2026-10-07 | S22: Chưa xác nhận | T22: day_16_toi_day21_test/day19/Day19_Red_Team_Test_Cases_Tran_Quoc_Nguyen.xlsx | U22: Product | V22: N | W22: N | X22: PA-05 | Y22: 05/10: chạy lại RT-041 và RT-045 vẫn nhận fallback; RT-001 (injection) vẫn bị chặn đúng | 07/10: RT-041, RT-045, RT-050 vẫn nhận fallback
A23: DEF-022 | B23: 19 | C23: BE Code runner | D23: STDERR lộ đường dẫn tuyệt đối của máy chủ | E23: Chạy code lỗi cú pháp: stderr có C:\Users\USER\AppData\Local\Temp\code-runner-<uuid>.py (RT-051) | F23: AI Safety | G23: High | H23: Recorded | I23: P1 | J23: Retest | K23: Runner trả nguyên traceback của Python, không chuẩn hóa tên file | L23: RC05 - Không lọc thông tin nội bộ trước khi trả cho người dùng | M23: Manual test | N23: Red-team thủ công | O23: BE | P23: 2026-10-01 | Q23: Not recorded | R23: 2026-10-07 | S23: Chưa xác nhận | T23: day_16_toi_day21_test/day19/Day19_Red_Team_Test_Cases_Tran_Quoc_Nguyen.xlsx | U23: Product | V23: N | W23: N | X23: PA-06 | Y23: 05/10: không retest được vì Docker sandbox chưa bật trên máy local | 07/10 (Docker đã bật): stderr chỉ còn /sandbox/<uuid>.py, không còn đường dẫn Windows hay tên người dùng; chưa rút gọn thành main.py như kỳ vọng
A24: DEF-023 | B24: 19 | C24: BE AI Coach | D24: AI Coach nhắc lại traceback có đường dẫn nội bộ | E24: Phân tích lỗi lần nộp gần nhất trích nguyên traceback kèm đường dẫn tạm (RT-052) | F24: AI Safety | G24: High | H24: Recorded | I24: P1 | J24: Open | K24: Debug loop đưa stderr thô vào prompt và vào câu trả lời, không qua bước lọc | L24: RC05 - Không lọc thông tin nội bộ trước khi trả cho người dùng | M24: Manual test | N24: Red-team thủ công | O24: BE | P24: 2026-10-01 | S24: Chưa xác nhận | T24: day_16_toi_day21_test/day19/Day19_Red_Team_Test_Cases_Tran_Quoc_Nguyen.xlsx | U24: Product | V24: N | W24: N | X24: PA-06 | Y24: Chưa retest ngày 05/10 | 07/10: không tạo được traceback để kiểm vì bài không có test case (DEF-056) | 07/10 (giao diện): vẫn chưa kiểm được; bài authoring tạo được traceback nhưng chấm ở trình duyệt nên không có submissionId cho debug loop
A25: DEF-024 | B25: 20 | C25: QA LLM Judge | D25: Judge v1 chấm lệch người ở 11/20 case | E25: Agreement v1 = 45% (9/20); ví dụ RT-002, RT-006 người chấm PASS nhưng judge chấm FAIL | F25: Evaluation | G25: Medium | H25: Proposed | I25: P2 | J25: Retest | K25: Prompt judge v1 không định nghĩa rõ 'attack không thành công' là PASS nên chấm theo độ đầy đủ của câu trả lời | L25: RC13 - Tiêu chí đánh giá AI chưa đủ rõ | M25: Local | N25: So sánh Human vs Judge | O25: QA | P25: 2026-10-01 | Q25: Not recorded | S25: Chưa xác nhận | T25: day_16_toi_day21_test/day20/Day20_LLM_Judge_Calibration_Tran_Quoc_Nguyen.xlsx | U25: Test tool | V25: N | W25: N | X25: PA-14 | Y25: Judge v2 đạt 20/20 trên cùng bộ; chưa kiểm trên holdout nên chưa đóng
A26: DEF-025 | B26: 22 | C26: QA tài liệu | D26: Báo cáo docx Ngày 22 ghi mapping cũ | E26: Bảng trong docx ghi 'Controller hoặc DTO → API contract' trong khi code chỉ đưa ra lưu ý cho người review | F26: Documentation | G26: Low | H26: Proposed | I26: P3 | J26: Open | K26: Docx được tạo ở vòng đầu và không cập nhật lại sau khi đổi mapping | L26: RC11 - Tài liệu/kết quả AI không được đối chiếu với code | M26: Local | N26: Đối chiếu docx với config | O26: QA | P26: 2026-10-05 | R26: 2026-10-07 | S26: Chưa xác nhận | T26: Day22_PR_Quality_Bot_Tran_Quoc_Nguyen/Bao_Cao_Ngay_22_PR_Quality_Bot_Tran_Quoc_Nguyen.docx | U26: Documentation | V26: N | W26: N | X26: PA-12 | Y26: 07/10: docx vẫn có dòng 'Controller hoặc DTO - API contract'
A27: DEF-026 | B27: 23 | C27: BE Auth, Quiz, Coach | D27: Gửi object thay cho chuỗi làm API trả 500 | E27: login với email/password là object; quiz/start với category là object; coach/chat với message là object: đều 500 Internal server error | F27: Data Validation | G27: High | H27: Proposed | I27: P1 | J27: Open | K27: DTO chỉ khai báo kiểu TypeScript, không có class-validator/ValidationPipe; service gọi thẳng email.trim() hoặc đưa object vào truy vấn | L27: RC01 - Không validate kiểu/định dạng input ở API | M27: Manual test | N27: Gọi API | O27: BE | P27: 2026-10-05 | R27: 2026-10-07 | S27: Chưa xác nhận | T27: Day23_Defect_Analytics_Tran_Quoc_Nguyen/evidence/live_test_2026-10-05.md | U27: Product | V27: N | W27: N | X27: PA-01 | Y27: 3 endpoint, cùng một nguyên nhân (N-01, N-04, N-05) | 07/10: cả 3 endpoint vẫn trả 500
A28: DEF-027 | B28: 23 | C28: BE Auth | D28: Đăng ký chấp nhận email sai định dạng | E28: Email 'khong-phai-email' được tạo tài khoản, trả 201 kèm token | F28: Data Validation | G28: Medium | H28: Proposed | I28: P2 | J28: Open | K28: Service chỉ kiểm rỗng và trùng, không kiểm định dạng email | L28: RC01 - Không validate kiểu/định dạng input ở API | M28: Manual test | N28: Gọi API | O28: BE | P28: 2026-10-05 | R28: 2026-10-07 | S28: Chưa xác nhận | T28: Day23_Defect_Analytics_Tran_Quoc_Nguyen/evidence/live_test_2026-10-05.md | U28: Product | V28: N | W28: N | X28: PA-01 | Y28: N-02 | 07/10: vẫn tạo được tài khoản với email sai định dạng
A29: DEF-028 | B29: 23 | C29: BE Quiz | D29: Nộp bài với answers không phải mảng vẫn được chấm và đóng lượt thi | E29: Body answers là chuỗi: 201, GRADED 0/200; nộp lại báo lượt thi đã kết thúc | F29: Data Validation | G29: Medium | H29: Proposed | I29: P2 | J29: Open | K29: SubmitAttemptDto không được validate; vòng lặp chấm bỏ qua dữ liệu sai kiểu thay vì từ chối | L29: RC01 - Không validate kiểu/định dạng input ở API | M29: Manual test | N29: Gọi API | O29: BE | P29: 2026-10-05 | R29: 2026-10-07 | S29: Chưa xác nhận | T29: Day23_Defect_Analytics_Tran_Quoc_Nguyen/evidence/live_test_2026-10-05.md | U29: Product | V29: N | W29: N | X29: PA-01 | Y29: N-03 | 07/10: vẫn 201 GRADED 0/200
A30: DEF-029 | B30: 23 | C30: DB local / seed | D30: Thẻ đề Python có trên giao diện nhưng DB không có câu hỏi Python | E30: Bắt đầu đề Python: 404 'Không tìm thấy câu hỏi nào'; DB chỉ có HTML5, CSS3, JavaScript, React, NestJS, Database, Quiz Engine | F30: Environment | G30: Medium | H30: Proposed | I30: P2 | J30: Open | K30: DB local được seed từ bộ dữ liệu cũ; file seed hiện tại (20 câu Python) chưa được nạp lại và không có bước kiểm seed khi khởi động | L30: RC08 - Môi trường/cấu hình không đồng bộ | M30: Manual test | N30: Gọi API + đọc trang | O30: BE | P30: 2026-10-05 | R30: 2026-10-07 | S30: Chưa xác nhận | T30: Day23_Defect_Analytics_Tran_Quoc_Nguyen/evidence/live_test_2026-10-05.md | U30: Environment | V30: N | W30: N | X30: PA-09 | Y30: N-06; cần kiểm trên môi trường của nhóm BE | 07/10: Python 404; HTML5 và CSS3 mỗi chủ đề chỉ có 2 câu trong khi thẻ ghi 20 câu | 07/10 (giao diện): bấm bắt đầu đề Python hiện 'Không tìm thấy câu hỏi nào trong hệ thống bài thi' (POST /quiz/start 404); đề HTML5 mở ra 2 câu
A31: DEF-030 | B31: 23 | C31: BE Auth | D31: Quên mật khẩu trả 500 với email đã đăng ký | E31: Email đã đăng ký: 500; email chưa đăng ký: 201 kèm thông báo chung, nên phân biệt được email nào tồn tại | F31: Authentication | G31: Medium | H31: Proposed | I31: P2 | J31: Needs verification | K31: Nghi do thiếu cấu hình GMAIL_USER/GMAIL_APP_PASSWORD ở máy local và lỗi gửi mail không được bắt; chưa xem log BE | L31: RC08 - Môi trường/cấu hình không đồng bộ | M31: Manual test | N31: Gọi API | O31: BE | P31: 2026-10-05 | R31: 2026-10-07 | S31: Chưa xác nhận | T31: Day23_Defect_Analytics_Tran_Quoc_Nguyen/evidence/live_test_2026-10-05.md | U31: Product | V31: N | W31: N | X31: PA-09 | Y31: N-07 | 07/10: vẫn 500 với email đã đăng ký
A32: DEF-031 | B32: 23 | C32: BE Code runner | D32: Thông báo lỗi sandbox lộ chi tiết hạ tầng | E32: Khi Docker chưa chạy, stderr trả cho học viên chứa 'npipe:////./pipe/dockerDesktopLinuxEngine' | F32: Backend Logic | G32: Low | H32: Proposed | I32: P3 | J32: Open | K32: Thông báo lỗi nội bộ của Docker được nối thẳng vào stderr trả về client | L32: RC05 - Không lọc thông tin nội bộ trước khi trả cho người dùng | M32: Manual test | N32: Gọi API | O32: BE | P32: 2026-10-05 | R32: 2026-10-07 | S32: Chưa xác nhận | T32: Day23_Defect_Analytics_Tran_Quoc_Nguyen/evidence/live_test_2026-10-05.md | U32: Product | V32: N | W32: N | X32: PA-06 | Y32: N-08 | 07/10 (Docker đã bật): lần chạy đầu stderr chứa log kéo image 'Unable to find image python:3.12-slim locally... Pulling fs layer'
A33: DEF-032 | B33: 23 | C33: DB local / seed | D33: Bài tập trong DB local không có test case | E33: 2/2 bài có testCaseCount 0; mọi bài nộp FAILED 'Bài tập thiếu Test Cases' | F33: Environment | G33: Medium | H33: Proposed | I33: P2 | J33: Open | K33: DB local không được seed bộ bài tập trong repo (initial-exercises*.ts) | L33: RC08 - Môi trường/cấu hình không đồng bộ | M33: Manual test | N33: Gọi API | O33: BE | P33: 2026-10-05 | R33: 2026-10-07 | S33: Chưa xác nhận | T33: Day23_Defect_Analytics_Tran_Quoc_Nguyen/evidence/live_test_2026-10-05.md | U33: Environment | V33: N | W33: N | X33: PA-09 | Y33: N-09; chặn retest RT-051 và F-D13-04 | 07/10: vẫn 2 bài, testCaseCount 0 | 07/10 (giao diện): Submit bài 'Tính tổng hai số nguyên A và B' hiện 'Lỗi hệ thống khi chấm bài (0/0 test) — Bài tập thiếu Test Cases'. 10 bài còn lại trên Playground đến từ /authoring/lessons, không phải từ /exercises
A34: DEF-033 | B34: 23 | C34: BE AI Coach | D34: Debug loop trả phản hồi vô nghĩa khi bài nộp không có kết quả test | E34: POST /coach/debug-loop với bài nộp FAILED do bài thiếu test: errorCategory WRONG_OUTPUT, feedback 'Sai ở test ?. Input: "undefined" — Kỳ vọng: "undefined"' | F34: Backend Logic | G34: Low | H34: Proposed | I34: P3 | J34: Open | K34: Debug loop giả định bài nộp luôn có ít nhất một test fail và đọc thẳng phần tử đầu của results; không có nhánh cho results rỗng | L34: RC09 - Thiếu test/gate tự động cho thay đổi | M34: Manual test | N34: Gọi API | O34: BE | P34: 2026-10-07 | R34: 2026-10-07 | S34: Chưa xác nhận | T34: Day23_Defect_Analytics_Tran_Quoc_Nguyen/evidence/live_test_2026-10-07.md | U34: Product | V34: N | W34: N | X34: PA-10 | Y34: N-10; chỉ xảy ra khi bài không có test case (DEF-056) | 07/10 (giao diện): bấm 'Phân tích lỗi lần nộp gần nhất' hiện thẻ 'Sai kết quả — Sai ở test ?. Input: "undefined"...'
A35: DEF-034 | B35: 23 | C35: FE Playground | D35: Bài do giáo viên soạn không thể đạt: test ẩn chạy với input rỗng | E35: Bài 'Kiểm tra số chẵn lẻ', nộp lời giải đúng: chỉ đạt 2/4, Test 3 và 4 (ẩn) báo EOFError. GET /authoring/lessons trả 18 test ẩn không có input/expectedOutput nhưng FE vẫn dùng để chấm | F35: Frontend Logic | G35: High | H35: Proposed | I35: P1 | J35: Open | K35: FE tự chấm bài authoring trong trình duyệt bằng /run (CodePlaygroundPage.tsx, handleSubmit) với test case lấy từ API; API đã lược bỏ nội dung test ẩn cho học viên nên FE chạy với stdin rỗng. Không có luồng chấm phía server cho bài authoring | L35: RC12 - Hợp đồng FE-BE không có nguồn chung | M35: Manual test | N35: Claude in Chrome + đọc code | O35: FE + BE | P35: 2026-10-07 | R35: 2026-10-07 | S35: Chưa xác nhận | T35: Day23_Defect_Analytics_Tran_Quoc_Nguyen/evidence/live_test_2026-10-07.md | U35: Product | V35: N | W35: N | X35: PA-13 | Y35: N-11; 25 bài authoring có test case, 18 test ẩn đều bị ảnh hưởng; kết quả chấm cũng không được lưu ở server
A36: DEF-035 | B36: 23 | C36: BE Code Runner | D36: check-syntax trả đường dẫn thư mục tạm của máy chủ kèm tên người dùng | E36: POST /exercises/check-syntax với code 'print(' trả errorMessage chứa C:\Users\<tên user>\AppData\Local\Temp\code-runner-syntax-...\<uuid>.py | F36: Backend Logic | G36: Medium | H36: Proposed | I36: P2 | J36: Open | K36: Bước kiểm cú pháp chạy trên máy chủ, ngoài sandbox, và trả nguyên stderr; phần cải thiện của DEF-034 chỉ thấy ở /run | L36: RC05 - Không lọc thông tin nội bộ trước khi trả cho người dùng | M36: Manual test | N36: Gọi API | O36: BE | P36: 2026-10-07 | R36: 2026-10-07 | S36: Chưa xác nhận | T36: Day23_Defect_Analytics_Tran_Quoc_Nguyen/evidence/live_test_2026-10-07.md | U36: Product | V36: N | W36: N | X36: PA-06 | Y36: N-12; cùng nhóm với DEF-034. Chưa xem thông báo này hiển thị thế nào trên giao diện
A37: DEF-036 | B37: 23 | C37: FE Quiz | D37: Trang kết quả quiz: câu chưa trả lời ghi là 'Sai', chữ cái đáp án không theo thứ tự | E37: Nộp đề HTML5 khi mới chọn 1/2 câu: câu 2 hiện 'Sai (0 điểm)', không phân biệt với chọn sai; câu 1 hiện đáp án theo thứ tự D, C, A, B | F37: Frontend UI | G37: Low | H37: Proposed | I37: P3 | J37: Open | K37: Trang review chỉ có hai trạng thái đúng/sai; nhãn chữ cái đi theo đáp án gốc sau khi xáo thứ tự (suy ra từ giao diện, chưa đọc code) | L37: RC09 - Thiếu test/gate tự động cho thay đổi | M37: Manual test | N37: Claude in Chrome | O37: FE | P37: 2026-10-07 | R37: 2026-10-07 | S37: Chưa xác nhận | T37: Day23_Defect_Analytics_Tran_Quoc_Nguyen/evidence/live_test_2026-10-07.md | U37: Product | V37: N | W37: N | X37: PA-10 | Y37: N-13; điểm số tính đúng (10/20, 50%)

Sheet Taxonomy
A1: Defect taxonomy dùng thống nhất cho toàn dự án
A3: Category
A4: Category | B4: Ví dụ
A5: Frontend UI | B5: Sai bố cục, thiếu label, focus, responsive
A6: Frontend Logic | B6: State sai, gọi API sai tham số
A7: Backend Logic | B7: Service xử lý sai nghiệp vụ, lộ thông tin nội bộ
A8: API Contract | B8: Thiếu field, sai status code so với hợp đồng
A9: Authentication | B9: Sai phân quyền, token, ownership
A10: Data Validation | B10: Không chặn input rỗng, sai kiểu, sai định dạng
A11: Content | B11: Bài học thiếu trường, link sai
A12: Quiz | B12: Đáp án trùng, lệch vị trí, lộ đáp án qua hình thức
A13: Coding Problem | B13: Test yếu, thiếu constraint, expected output sai
A14: RAG Retrieval | B14: Xếp hạng/citation kém đi
A15: AI Safety | B15: Prompt injection, child safety, lộ dữ liệu qua AI
... A22: Documentation | B22: Tài liệu/bảng tính không khớp code hoặc lỗi công thức
A24: Severity
A25: Severity | B25: Định nghĩa
A26: Critical | B26: Sai kết quả học tập, lộ dữ liệu, mất an toàn; phải chặn release | Priority mặc định P0
A27: High | B27: Chức năng chính sai hoặc rủi ro bảo mật/an toàn rõ | Priority mặc định P1
A28: Medium | B28: Ảnh hưởng một phần, có cách vòng | Priority mặc định P2
A29: Low | B29: Thẩm mỹ, chất lượng nội dung nhẹ, công cụ nội bộ | Priority mặc định P3
A31: Status
A32: Status | B32: Ý nghĩa
A33: Open | B33: Đã xác nhận, chưa sửa
A34: In Progress | B34: Đang sửa
A35: Fixed | B35: Đã sửa, có bằng chứng sửa
A36: Retest | B36: Đã sửa một phần hoặc chờ kiểm lại đủ điều kiện
A37: Closed | B37: Đã kiểm lại và đạt
A38: Needs verification | B38: Chưa đủ bằng chứng để kết luận là lỗi thật
A40: Root Cause Category
A41: Root Cause Category
A42: RC01 - Không validate kiểu/định dạng input ở API
A43: RC02 - Tin dữ liệu từ client, thiếu kiểm quyền ở server
A44: RC03 - Nội dung/dữ liệu học liệu đưa vào không qua gate tự động
A45: RC04 - Guardrail AI chưa phủ tình huống
A46: RC05 - Không lọc thông tin nội bộ trước khi trả cho người dùng
A47: RC06 - Fixture/dữ liệu test không được kiểm độc lập
A48: RC07 - Công cụ test sai giả định
A49: RC08 - Môi trường/cấu hình không đồng bộ
A50: RC09 - Thiếu test/gate tự động cho thay đổi
...

Sheet Dashboard
A1: DEFECT DASHBOARD - CyberSoft Learning Hub (Ngày 6 đến Ngày 23)
A2: Sinh lúc 2026-10-05 16:39 ICT | Người làm: Trần Quốc Nguyên | Cập nhật 2026-10-07: test lại web local, bỏ 25 lỗi đã hết khỏi log | Mọi số bên dưới là công thức đếm trên sheet Defect_Log, không nhập tay.
A4: KPI
A5: Tổng số defect | B5: =COUNTA(Defect_Log!$A$2:$A$37) -> 36
A6: Đang mở (Open + In Progress) | B6: =COUNTIF(Defect_Log!$J$2:$J$37,"Open")+COUNTIF(Defect_Log!$J$2:$J$37,"In Progress") -> 27
A7: Đã sửa/đã đóng (Fixed + Closed) - đã bỏ khỏi log ngày 07/10 | B7: =COUNTIF(Defect_Log!$J$2:$J$37,"Fixed")+COUNTIF(Defect_Log!$J$2:$J$37,"Closed") -> 0
A8: Chờ kiểm lại (Retest) | B8: =COUNTIF(Defect_Log!$J$2:$J$37,"Retest") -> 5
A9: Cần xác minh (Needs verification) | B9: =COUNTIF(Defect_Log!$J$2:$J$37,"Needs verification") -> 4
A10: Critical/High còn mở | B10: =COUNTIFS(Defect_Log!$J$2:$J$37,"Open",Defect_Log!$G$2:$G$37,"Critical")+COUNTIFS(Defect_Log!$J$2:$J$37,"Open",Defect_Log!$G$2:$G$37,"High") -> 6
A11: Fixture bug | B11: =COUNTIF(Defect_Log!$V$2:$V$37,"Y") -> 0
A12: Regression | B12: =COUNTIF(Defect_Log!$W$2:$W$37,"Y") -> 1
A13: Lỗi sản phẩm (Defect Kind = Product) | B13: =COUNTIF(Defect_Log!$U$2:$U$37,"Product") -> 30
A14: Lỗi do test hoặc môi trường (fixture + tool + environment + CI) | B14: =COUNTIF(Defect_Log!$U$2:$U$37,"Test fixture")+COUNTIF(Defect_Log!$U$2:$U$37,"Test tool")+COUNTIF(Defect_Log!$U$2:$U$37,"Environment")+COUNTIF(Defect_Log!$U$2:$U$37,"CI/Process") -> 3
A15: Defect phát hiện ở Ngày 23 (test web local 05/10, 07/10) | B15: =COUNTIF(Defect_Log!$B$2:$B$37,23) -> 11
A16: Thời gian xử lý trung bình | B16: Not recorded
A18: Ghi chú: báo cáo gốc không ghi ngày sửa cho đa số lỗi, nên không tính thời gian xử lý. Owner là nhóm đề xuất; chưa có deadline nào được giao chính thức.
A20: Defect theo status
A21: Status | B21: Số defect
A22: Open | B22: =COUNTIF(Defect_Log!$J$2:$J$37,"Open") -> 27
A23: In Progress | B23: =COUNTIF(Defect_Log!$J$2:$J$37,"In Progress") -> 0
A24: Fixed | B24: =COUNTIF(Defect_Log!$J$2:$J$37,"Fixed") -> 0
A25: Retest | B25: =COUNTIF(Defect_Log!$J$2:$J$37,"Retest") -> 5
A26: Closed | B26: =COUNTIF(Defect_Log!$J$2:$J$37,"Closed") -> 0
A27: Needs verification | B27: =COUNTIF(Defect_Log!$J$2:$J$37,"Needs verification") -> 4
A29: Defect theo severity
A30: Severity | B30: Số defect
A31: Critical | B31: =COUNTIF(Defect_Log!$G$2:$G$37,"Critical") -> 0
A32: High | B32: =COUNTIF(Defect_Log!$G$2:$G$37,"High") -> 9
A33: Medium | B33: =COUNTIF(Defect_Log!$G$2:$G$37,"Medium") -> 18
A34: Low | B34: =COUNTIF(Defect_Log!$G$2:$G$37,"Low") -> 9
A36: Defect theo defect kind
A37: Defect kind | B37: Số defect
A38: Product | B38: =COUNTIF(Defect_Log!$U$2:$U$37,"Product") -> 30
A39: Test fixture | B39: =COUNTIF(Defect_Log!$U$2:$U$37,"Test fixture") -> 0
A40: Test tool | B40: =COUNTIF(Defect_Log!$U$2:$U$37,"Test tool") -> 1
A41: Environment | B41: =COUNTIF(Defect_Log!$U$2:$U$37,"Environment") -> 2
A42: CI/Process | B42: =COUNTIF(Defect_Log!$U$2:$U$37,"CI/Process") -> 0
A43: Documentation | B43: =COUNTIF(Defect_Log!$U$2:$U$37,"Documentation") -> 2
A44: External | B44: =COUNTIF(Defect_Log!$U$2:$U$37,"External") -> 1
A46: Defect theo category
...

Sheet Pareto
A1: Pareto theo Root Cause Category
A2: Số lỗi = COUNTIF trên cột Root Cause Category của Defect_Log. Thứ tự sắp xếp được chốt lúc sinh file theo số lỗi giảm dần.
A4: Root Cause Category | B4: Số lỗi | C4: Tỷ lệ | D4: Tích lũy | E4: Còn mở | F4: Trong top 5 RCA?
A5: RC10 - Component UI không theo chuẩn a11y/responsive | B5: =COUNTIF(Defect_Log!$L$2:$L$37,A5) -> 7 | C5: =B5/$B$18 -> 0.19444444 | D5: =SUM($B$5:B5)/$B$18 -> 0.19444444 | E5: =COUNTIFS(Defect_Log!$L$2:$L$37,A5,Defect_Log!$J$2:$J$37,"Open") -> 5 | F5: Có
A6: RC03 - Nội dung/dữ liệu học liệu đưa vào không qua gate tự động | B6: =COUNTIF(Defect_Log!$L$2:$L$37,A6) -> 6 | C6: =B6/$B$18 -> 0.16666667 | D6: =SUM($B$5:B6)/$B$18 -> 0.36111111 | E6: =COUNTIFS(Defect_Log!$L$2:$L$37,A6,Defect_Log!$J$2:$J$37,"Open") -> 6 | F6: Có
A7: RC05 - Không lọc thông tin nội bộ trước khi trả cho người dùng | B7: =COUNTIF(Defect_Log!$L$2:$L$37,A7) -> 6 | C7: =B7/$B$18 -> 0.16666667 | D7: =SUM($B$5:B7)/$B$18 -> 0.52777778 | E7: =COUNTIFS(Defect_Log!$L$2:$L$37,A7,Defect_Log!$J$2:$J$37,"Open") -> 3 | F7: Có
A8: RC09 - Thiếu test/gate tự động cho thay đổi | B8: =COUNTIF(Defect_Log!$L$2:$L$37,A8) -> 5 | C8: =B8/$B$18 -> 0.13888889 | D8: =SUM($B$5:B8)/$B$18 -> 0.66666667 | E8: =COUNTIFS(Defect_Log!$L$2:$L$37,A8,Defect_Log!$J$2:$J$37,"Open") -> 3
A9: RC01 - Không validate kiểu/định dạng input ở API | B9: =COUNTIF(Defect_Log!$L$2:$L$37,A9) -> 4 | C9: =B9/$B$18 -> 0.11111111 | D9: =SUM($B$5:B9)/$B$18 -> 0.77777778 | E9: =COUNTIFS(Defect_Log!$L$2:$L$37,A9,Defect_Log!$J$2:$J$37,"Open") -> 4 | F9: Có
A10: RC08 - Môi trường/cấu hình không đồng bộ | B10: =COUNTIF(Defect_Log!$L$2:$L$37,A10) -> 3 | C10: =B10/$B$18 -> 0.083333333 | D10: =SUM($B$5:B10)/$B$18 -> 0.86111111 | E10: =COUNTIFS(Defect_Log!$L$2:$L$37,A10,Defect_Log!$J$2:$J$37,"Open") -> 2
A11: RC11 - Tài liệu/kết quả AI không được đối chiếu với code | B11: =COUNTIF(Defect_Log!$L$2:$L$37,A11) -> 2 | C11: =B11/$B$18 -> 0.055555556 | D11: =SUM($B$5:B11)/$B$18 -> 0.91666667 | E11: =COUNTIFS(Defect_Log!$L$2:$L$37,A11,Defect_Log!$J$2:$J$37,"Open") -> 2
A12: RC04 - Guardrail AI chưa phủ tình huống | B12: =COUNTIF(Defect_Log!$L$2:$L$37,A12) -> 1 | C12: =B12/$B$18 -> 0.027777778 | D12: =SUM($B$5:B12)/$B$18 -> 0.94444444 | E12: =COUNTIFS(Defect_Log!$L$2:$L$37,A12,Defect_Log!$J$2:$J$37,"Open") -> 1 | F12: Có
A13: RC12 - Hợp đồng FE-BE không có nguồn chung | B13: =COUNTIF(Defect_Log!$L$2:$L$37,A13) -> 1 | C13: =B13/$B$18 -> 0.027777778 | D13: =SUM($B$5:B13)/$B$18 -> 0.97222222 | E13: =COUNTIFS(Defect_Log!$L$2:$L$37,A13,Defect_Log!$J$2:$J$37,"Open") -> 1
A14: RC13 - Tiêu chí đánh giá AI chưa đủ rõ | B14: =COUNTIF(Defect_Log!$L$2:$L$37,A14) -> 1 | C14: =B14/$B$18 -> 0.027777778 | D14: =SUM($B$5:B14)/$B$18 -> 1 | E14: =COUNTIFS(Defect_Log!$L$2:$L$37,A14,Defect_Log!$J$2:$J$37,"Open") -> 0
A15: RC02 - Tin dữ liệu từ client, thiếu kiểm quyền ở server | B15: =COUNTIF(Defect_Log!$L$2:$L$37,A15) -> 0 | C15: =B15/$B$18 -> 0 | D15: =SUM($B$5:B15)/$B$18 -> 1 | E15: =COUNTIFS(Defect_Log!$L$2:$L$37,A15,Defect_Log!$J$2:$J$37,"Open") -> 0
A16: RC06 - Fixture/dữ liệu test không được kiểm độc lập | B16: =COUNTIF(Defect_Log!$L$2:$L$37,A16) -> 0 | C16: =B16/$B$18 -> 0 | D16: =SUM($B$5:B16)/$B$18 -> 1 | E16: =COUNTIFS(Defect_Log!$L$2:$L$37,A16,Defect_Log!$J$2:$J$37,"Open") -> 0
A17: RC07 - Công cụ test sai giả định | B17: =COUNTIF(Defect_Log!$L$2:$L$37,A17) -> 0 | C17: =B17/$B$18 -> 0 | D17: =SUM($B$5:B17)/$B$18 -> 1 | E17: =COUNTIFS(Defect_Log!$L$2:$L$37,A17,Defect_Log!$J$2:$J$37,"Open") -> 0
A18: Tổng | B18: =SUM(B5:B17) -> 36 | C18: =SUM(C5:C17) -> 1 | E18: =SUM(E5:E17) -> 27
A20: Sau khi bỏ các lỗi đã hết (07/10), Pareto còn: RC10 7, RC03 6, RC05 6, RC09 5, RC01 4, RC08 3. Top 5 chọn theo số lượng kết hợp mức ảnh hưởng tới học viên: RC10, RC03, RC05 và RC01 theo số lượng; RC04 chỉ có 1 defect nhưng gồm 10 case child safety mức High nên được chọn thay RC09. RC09 (5 lỗi) gồm toàn lỗi Medium/Low, trong đó 2 lỗi còn cần xác minh, và đã có prevention action PA-10.

Sheet RCA_Top5
A1: RCA cho 5 nhóm nguyên nhân gốc
A2: Sau khi bỏ các lỗi đã hết (07/10), Pareto còn: RC10 7, RC03 6, RC05 6, RC09 5, RC01 4, RC08 3. Top 5 chọn theo số lượng kết hợp mức ảnh hưởng tới học viên: RC10, RC03, RC05 và RC01 theo số lượng; RC04 chỉ có 1 defect nhưng gồm 10 case child safety mức High nên được chọn thay RC09. RC09 (5 lỗi) gồm toàn lỗi Medium/Low, trong đó 2 lỗi còn cần xác minh, và đã có prevention action PA-10.
A4: # | B4: Root Cause Category | C4: Nhóm lỗi | D4: Defect liên quan | E4: Số lỗi | F4: Symptom (tester quan sát) | G4: Impact | H4: Root cause | I4: Contributing factors | J4: Detection | K4: Corrective action (sửa lỗi hiện tại) | L4: Preventive action | M4: Owner | N4: Deadline
A5: 1 | B5: RC10 - Component UI không theo chuẩn a11y/responsive | C5: Form, focus và bố cục không đạt chuẩn truy cập/responsive | D5: DEF-004..DEF-010 | E5: =COUNTIF(Defect_Log!$L$2:$L$37,B5) -> 7 | F5: WAVE báo thiếu label ở Login, Register, Playground; không chọn được đề bằng bàn phím; header và thẻ Hint tràn ở iPad Pro. | G5: Học viên dùng trình đọc màn hình hoặc bàn phím không hoàn thành được đăng nhập/làm quiz; nhóm tuổi nhỏ dùng tablet gặp bố cục vỡ. | H5: Các component dùng chung (ô nhập, thẻ đề, Header) được dựng không theo chuẩn: label không liên kết input, thẻ bấm được không phải button, không có breakpoint tablet. | I5: Không có kiểm a11y tự động trong FE; checklist review chưa có mục a11y/responsive; lỗi từ Ngày 9 đến 05/10 vẫn còn vì chưa ai được giao. | J5: Kiểm thủ công + WAVE Ngày 9; xác nhận lại DOM ngày 05/10. | K5: Sửa component form (id + htmlFor), đổi thẻ đề thành button, thêm breakpoint tablet. | L5: PA-11 | M5: FE (đề xuất, chưa xác nhận) | N5: Chưa xác nhận
A6: 2 | B6: RC03 - Nội dung/dữ liệu học liệu đưa vào không qua gate tự động | C6: Nội dung học liệu sai/thiếu lọt vào seed | D6: DEF-012, DEF-014, DEF-015, DEF-018, DEF-019, DEF-020 | E6: =COUNTIF(Defect_Log!$L$2:$L$37,B6) -> 6 | F6: Validator báo bài học thiếu mục tiêu, đáp án dồn về một vị trí, bài coding thiếu ràng buộc và bộ test để lọt lời giải sai. | G6: Học viên đoán được đáp án theo vị trí; lời giải sai có thể được chấm đạt; chất lượng học liệu không đồng đều. | H6: Dữ liệu học liệu được soạn tay trong file .ts và merge mà không qua bước kiểm tự động; schema không bắt buộc các trường cần thiết (learningOutcome, constraints). | I6: Trước Ngày 22 không có gate nội dung trong PR; chưa có tiêu chí soạn phương án nhiễu và số test tối thiểu. | J6: content-lint (Ngày 11), quiz-validator (Ngày 12), coding-problem-validator + mutation test (Ngày 13). | K6: Bổ sung trường còn thiếu, xáo lại vị trí đáp án, áp bộ hidden test bổ sung. | L6: PA-03 (đã xong), PA-04 | M6: BE (đề xuất, chưa xác nhận) | N6: Chưa xác nhận
A7: 3 | B7: RC01 - Không validate kiểu/định dạng input ở API | C7: API nhận input sai kiểu/sai định dạng | D7: DEF-050, DEF-051, DEF-052 (và DEF-026 ở hệ thống demo) | E7: =COUNTIF(Defect_Log!$L$2:$L$37,B7) -> 4 | F7: Gửi object thay cho chuỗi làm 3 endpoint trả 500; email sai định dạng vẫn tạo được tài khoản; answers sai kiểu vẫn được chấm và đóng lượt thi. | G7: Kẻ xấu gây lỗi 500 hàng loạt; dữ liệu rác vào DB; học viên mất lượt thi vì một request hỏng. | H7: BE không bật ValidationPipe và DTO không có ràng buộc kiểm tra, nên kiểu khai báo TypeScript không được thực thi lúc chạy. | I7: Spec hiện tại chỉ kiểm luồng đúng và thiếu trường; contract test Ngày 6 chạy trên API mô phỏng nên không chạm BE thật. | J7: Test API thủ công ngày 05/10 (Ngày 23). | K7: Thêm kiểm kiểu cho 5 chỗ đã nêu. | L7: PA-01 | M7: BE (đề xuất, chưa xác nhận) | N7: Chưa xác nhận
A8: 4 | B8: RC05 - Không lọc thông tin nội bộ trước khi trả cho người dùng | C8: Thông tin nội bộ lộ ra cho học viên | D8: DEF-021, DEF-024, DEF-034, DEF-035, DEF-055, DEF-060 | E8: =COUNTIF(Defect_Log!$L$2:$L$37,B8) -> 6 | F8: STDERR và AI Coach hiện đường dẫn tuyệt đối của máy chủ; thông báo Docker lộ tên pipe; nghi lộ input hidden test và lời giải qua hint. | G8: Lộ cấu trúc máy chủ và có thể lộ test ẩn/lời giải, làm mất giá trị chấm điểm. | H8: Dữ liệu thô từ runner/DB (traceback, stderr, object hints) được trả thẳng cho client và đưa vào prompt, không qua lớp lọc theo vai trò người nhận. | I8: Không có spec kiểm 'response không chứa chuỗi nội bộ'; red-team chỉ làm thủ công ở Ngày 19. | J8: Red-team Ngày 19, đọc code Ngày 13, test API ngày 05/10. | K8: Chuẩn hóa traceback, không trả stderr của test ẩn, loại hints khỏi API chi tiết (đã thấy sửa trên bài kiểm được). | L8: PA-06 | M8: BE (đề xuất, chưa xác nhận) | N8: Chưa xác nhận
A9: 5 | B9: RC04 - Guardrail AI chưa phủ tình huống | C9: AI Coach thiếu guardrail an toàn cho trẻ | D9: DEF-033 (10 case RT-041..RT-050) | E9: =COUNTIF(Defect_Log!$L$2:$L$37,B9) -> 1 | F9: Với yêu cầu nội dung không phù hợp cho trẻ, AI Coach trả lời fallback về bài tập, không từ chối rõ và không hướng dẫn tìm hỗ trợ. | G9: Sản phẩm phục vụ lớp 3-12; phản hồi không nhận diện tình huống nhạy cảm là rủi ro an toàn và uy tín. | H9: Bộ lọc trước LLM chỉ có nhánh prompt injection; không có nhánh child safety nên câu hỏi rơi vào câu trả lời mặc định. | I9: Bộ eval 100 case của Coach không có nhóm child safety; ngưỡng release chưa nêu yêu cầu này. | J9: Red-team thủ công Ngày 19; chạy lại 2 case ngày 05/10. | K9: Thêm nhánh từ chối và hướng dẫn an toàn. | L9: PA-05 | M9: BE (đề xuất, chưa xác nhận) | N9: Chưa xác nhận
A11: Owner và Deadline chưa được quản lý giao chính thức; đây là thông tin cần mentor/trưởng nhóm bổ sung.

Sheet Prevention_Actions
A1: Prevention actions
A2: Owner là nhóm đề xuất. Deadline 'Chưa xác nhận' nghĩa là chưa ai giao hạn thật; cần quản lý bổ sung.
A4: Action ID | B4: Root Cause Category | C4: Action (việc cụ thể) | D4: Owner Team (đề xuất) | E4: Owner xác nhận? | F4: Deadline | G4: Priority | H4: Verification (cách xác nhận hoàn thành) | I4: Status | J4: Số defect liên quan | K4: Ghi chú
A5: PA-01 | B5: RC01 - Không validate kiểu/định dạng input ở API | C5: Bật ValidationPipe toàn cục (whitelist, transform) và thêm class-validator cho DTO của auth, quiz, coach; viết spec gửi sai kiểu cho từng endpoint | D5: BE | E5: Chưa xác nhận | F5: Chưa xác nhận | G5: P1 | H5: 5 request N-01..N-05 trong evidence Ngày 23 trả 400; spec mới chạy trong gate Backend của PR bot | I5: Proposed | J5: =COUNTIF(Defect_Log!$X$2:$X$37,A5) -> 3
A6: PA-02 | B6: RC02 - Tin dữ liệu từ client, thiếu kiểm quyền ở server | C6: Thêm spec Jest khóa lỗi ownership của quiz: user B review/submit attempt của user A phải nhận 404 | D6: BE | E6: Chưa xác nhận | F6: Chưa xác nhận | G6: P2 | H6: Spec có trong learning-hub/BE và pass ở gate Backend | I6: Proposed | J6: =COUNTIF(Defect_Log!$X$2:$X$37,A6) -> 0 | K6: Code đã sửa; action này để lỗi không quay lại
A7: PA-03 | B7: RC03 - Nội dung/dữ liệu học liệu đưa vào không qua gate tự động | C7: Đưa validator quiz, bài coding, bài học vào PR gate khi file dữ liệu thay đổi | D7: QA | E7: QA (đã làm) | F7: 2026-10-05 (đã xong) | G7: P1 | H7: PR sửa initial-quiz-questions.ts tự chạy gate 'Quiz validator - câu hỏi thật' | I7: Done | J7: =COUNTIF(Defect_Log!$X$2:$X$37,A7) -> 3 | K7: Đã có từ PR #98 ngày 05/10; gate bài học đang advisory
A8: PA-04 | B8: RC03 - Nội dung/dữ liệu học liệu đưa vào không qua gate tự động | C8: Thêm trường constraints vào schema Exercise và bổ sung cho 24 bài; áp bộ hidden test bổ sung (overrides.json); đặt tối thiểu 4 test và 2 hidden | D8: BE | E8: Chưa xác nhận | F8: Chưa xác nhận | G8: P2 | H8: Validator bài coding không còn CP002/CP013; mutation score bài số nguyên tố ≥ 80% | I8: Proposed | J8: =COUNTIF(Defect_Log!$X$2:$X$37,A8) -> 5 | K8: Sau khi xong, sửa 2 lỗi CT004 rồi chuyển gate bài học sang blocking
A9: PA-05 | B9: RC04 - Guardrail AI chưa phủ tình huống | C9: Thêm nhánh child-safety vào bộ lọc trước LLM của AI Coach (từ chối rõ + hướng dẫn tìm người lớn hỗ trợ) và đưa 10 case RT-041..050 vào coach eval spec | D9: BE | E9: Chưa xác nhận | F9: Chưa xác nhận | G9: P1 | H9: 10 case RT-041..050 PASS trong coach-eval.spec.ts; chạy lại thủ công RT-041, RT-045 | I9: Proposed | J9: =COUNTIF(Defect_Log!$X$2:$X$37,A9) -> 1
A10: PA-06 | B10: RC05 - Không lọc thông tin nội bộ trước khi trả cho người dùng | C10: Lọc stderr/traceback trước khi trả FE và trước khi đưa vào prompt: đổi đường dẫn thành main.py, ẩn chi tiết Docker; không trả stderr của hidden test; thêm spec kiểm chuỗi 'C:\', '/tmp', 'npipe' | D10: BE | E10: Chưa xác nhận | F10: Chưa xác nhận | G10: P1 | H10: RT-051, RT-052 PASS; response run/submit không chứa đường dẫn tuyệt đối | I10: Proposed | J10: =COUNTIF(Defect_Log!$X$2:$X$37,A10) -> 6
A11: PA-07 | B11: RC06 - Fixture/dữ liệu test không được kiểm độc lập | C11: Quy ước cho mọi bộ fixture: có manifest ghi rule mục tiêu và có script kiểm độc lập chạy trong bộ test; dữ liệu sinh tự động phải qua validator trước khi xuất | D11: QA | E11: Chưa xác nhận | F11: Chưa xác nhận | G11: P2 | H11: Mỗi thư mục fixtures có check-fixtures chạy trong node --test/unittest | I11: In Progress | J11: =COUNTIF(Defect_Log!$X$2:$X$37,A11) -> 0 | K11: Đã có ở Ngày 12, 15, 22; chưa viết thành quy ước chung
A12: PA-08 | B12: RC07 - Công cụ test sai giả định | C12: Mỗi rule mới của validator/bot phải có ít nhất 1 ca từ dữ liệu thật ở cả hai chiều (bắt đúng và không báo oan) trước khi dùng làm gate | D12: QA | E12: Chưa xác nhận | F12: Chưa xác nhận | G12: P2 | H12: Checklist review có mục này; test tương ứng tồn tại trong tools/*/tests | I12: Proposed | J12: =COUNTIF(Defect_Log!$X$2:$X$37,A12) -> 0
A13: PA-09 | B13: RC08 - Môi trường/cấu hình không đồng bộ | C13: Viết script seed chuẩn và kiểm seed khi khởi động dev (đếm câu hỏi theo category, testCaseCount > 0); bổ sung .env.example cho Gmail SMTP và bắt lỗi gửi mail; ghi phiên bản Node/Python dùng chung | D13: BE | E13: Chưa xác nhận | F13: Chưa xác nhận | G13: P2 | H13: Sau khi seed: đề Python trả 20 câu, bài tập có test; forgot-password trả cùng một thông báo cho mọi email | I13: Proposed | J13: =COUNTIF(Defect_Log!$X$2:$X$37,A13) -> 3
A14: PA-10 | B14: RC09 - Thiếu test/gate tự động cho thay đổi | C14: Mở rộng PR Quality Bot: chạy cả khi push thẳng vào main, thêm gate cho Data-AI-Resource, đề nghị admin bật bắt buộc check trước khi merge | D14: QA | E14: Chưa xác nhận | F14: Chưa xác nhận | G14: P2 | H14: Push vào main tạo run trong tab Actions; PR sửa Data-AI-Resource chạy test của nhóm Data | I14: Proposed | J14: =COUNTIF(Defect_Log!$X$2:$X$37,A14) -> 3 | K14: Phần cơ bản (bot chạy trên PR) đã xong ngày 05/10
A15: PA-11 | B15: RC10 - Component UI không theo chuẩn a11y/responsive | C15: Sửa component form dùng chung (id + htmlFor), thêm style focus-visible, breakpoint tablet cho Header và lưới Hint; thêm kiểm a11y tự động (eslint-plugin-jsx-a11y hoặc axe) cho Login, Register, Playground | D15: FE | E15: Chưa xác nhận | F15: Chưa xác nhận | G15: P2 | H15: WAVE không còn missing form label trên 3 trang; ảnh iPad Pro không còn tràn | I15: Proposed | J15: =COUNTIF(Defect_Log!$X$2:$X$37,A15) -> 7
A16: PA-12 | B16: RC11 - Tài liệu/kết quả AI không được đối chiếu với code | C16: Trước khi nộp: đối chiếu bảng trong docx/xlsx với config và code; sửa docx Ngày 22 và công thức #REF! Ngày 10 | D16: QA | E16: Chưa xác nhận | F16: Chưa xác nhận | G16: P3 | H16: Docx Ngày 22 khớp change-impact-map.json; sheet 06_Thresholds không còn #REF! | I16: Proposed | J16: =COUNTIF(Defect_Log!$X$2:$X$37,A16) -> 2
A17: PA-13 | B17: RC12 - Hợp đồng FE-BE không có nguồn chung | C17: BE cung cấp API danh sách đề (id, chủ đề, số câu, thời lượng); FE đọc từ API thay vì khai sẵn trong QuizTakingPage | D17: FE + BE | E17: Chưa xác nhận | F17: Chưa xác nhận | G17: P2 | H17: Regression quiz-contract.spec.ts BUG-01 PASS trên DB đã seed đủ | I17: Proposed | J17: =COUNTIF(Defect_Log!$X$2:$X$37,A17) -> 1
A18: PA-14 | B18: RC13 - Tiêu chí đánh giá AI chưa đủ rõ | C18: Tạo holdout tối thiểu 20 case chưa dùng để chỉnh prompt và chạy Judge v2; ghi agreement riêng cho holdout | D18: QA | E18: Chưa xác nhận | F18: Chưa xác nhận | G18: P2 | H18: Workbook Ngày 20 có sheet Holdout và agreement ≥ 90% | I18: Proposed | J18: =COUNTIF(Defect_Log!$X$2:$X$37,A18) -> 1
